<?xml version="1.0" ?>
<!-- Example adapted from http://wiki.ros.org/urdf/Tutorials/Create%20your%20own%20urdf%20file -->

<robot name="test_robot">
  <link name="link1">
    <inertial>
      <origin rpy="0.0 0.0 0" xyz="0.0 0.0 0.0"/>
      <mass value="1.0"/>
      <inertia ixx="0.01" ixy="-1.0e-05" ixz="1.0e-05" iyy="1.0e-5" iyz="1.0e-5" izz="0.01"/>
    </inertial>
  </link>
  <link name="link2">
    <inertial>
      <origin rpy="0.0 0.0 0" xyz="0.0 0.0 0.0"/>
      <mass value="2.0"/>
      <inertia ixx="0.01" ixy="-1.0e-05" ixz="1.0e-05" iyy="1.0e-5" iyz="1.0e-5" izz="0.01"/>
    </inertial>
  </link>
  <link name="link3">
    <inertial>
      <origin rpy="0.0 0.0 0" xyz="0.0 0.0 0.0"/>
      <mass value="3.0"/>
      <inertia ixx="0.01" ixy="-1.0e-05" ixz="1.0e-05" iyy="1.0e-5" iyz="1.0e-5" izz="0.01"/>
    </inertial>
  </link>
  <link name="link4">
    <inertial>
      <origin rpy="0.0 0.0 0" xyz="0.0 0.0 0.0"/>
      <mass value="4.0"/>
      <inertia ixx="0.01" ixy="-1.0e-05" ixz="1.0e-05" iyy="1.0e-5" iyz="1.0e-5" izz="0.01"/>
    </inertial>
  </link>

  <joint name="joint1" type="continuous">
    <parent link="link1"/>
    <child link="link2"/>
    <origin xyz="5 3 0" rpy="0 0 0" />
    <axis xyz="-0.9 0.15 0" />
  </joint>

  <joint name="joint2" type="continuous">
    <parent link="link1"/>
    <child link="link3"/>
    <origin xyz="-2 5 0" rpy="0 0 1.57" />
    <axis xyz="-0.707 0.707 0" />
  </joint>

  <joint name="joint3" type="continuous">
    <parent link="link3"/>
    <child link="link4"/>
    <origin xyz="5 0 0" rpy="0 0 -1.57" />
    <axis xyz="0.707 -0.707 0" />
  </joint>
</robot>
