<?xml version="1.0" ?>
<!-- Example adapted from http://wiki.ros.org/urdf/Tutorials/Create%20your%20own%20urdf%20file -->

<robot name="test_robot" xmlns:xacro="http://www.ros.org/wiki/xacro">

<xacro:macro name="link_withJoint" params="name parent">
  <link name="${name}">
    <inertial>
      <origin rpy="0.0 0.0 0" xyz="0.0 0.0 0.0"/>
      <mass value="1.0"/>
      <inertia ixx="0.01" ixy="-1.0e-05" ixz="1.0e-05" iyy="1.0e-5" iyz="1.0e-5" izz="0.01"/>
    </inertial>
  </link>
  <joint name="${name}_joint" type="continuous">
    <parent link="${parent}"/>
    <child link="${name}"/>
    <origin xyz="1 0 0" rpy="0 0 0" />
    <axis xyz="1.0 0 0" />
  </joint>
</xacro:macro>


  <link name="link1">
    <inertial>
      <origin rpy="0.0 0.0 0" xyz="0.0 0.0 0.0"/>
      <mass value="1.0"/>
      <inertia ixx="0.01" ixy="-1.0e-05" ixz="1.0e-05" iyy="1.0e-5" iyz="1.0e-5" izz="0.01"/>
    </inertial>
  </link>

  <xacro:link_withJoint name="link2" parent="link1"/>
  <xacro:link_withJoint name="link3" parent="link1"/>
  <xacro:link_withJoint name="link4" parent="link3"/>

</robot>
